Workbook

Sheet Usage of Sheet
A1: Use of this Excel sheet
A2: Data Type | B2: Color Code | C2: Type of Data
A3: 1 | C3: Optional Data
A4: 2 | C4: Mandatory Data
A5: 3 | C5: Don’t change the Data
A6: 4 | C6: No need to provide the Data

Sheet Home Page
B3: Feature Name | C3: Available Scripts | D3: GUI | E3: CLI | F3: Service Affecting Test Case Count | G3: Need to execute (Non SA) | H3: Need to execute (SA)
B4: PMIC | C4: =SUM(D4,E4) -> 66 | D4: =COUNTIF(PMIC!AA:AA, "GUI") -> 66 | E4: =COUNTIF(PMIC!AA:AA, "CLI") -> 0 | F4: =COUNTIF(PMIC!BB:BB, "Yes") -> 0 | G4: =COUNTIFS(PMIC!A:A, "Y", PMIC!AB:AB, "No") -> 45 | H4: =COUNTIFS(PMIC!A:A, "Y", PMIC!AB:AB, "Yes") -> 0
B5: Add Node (Web) | C5: =SUM(D5,E5) -> 3 | D5: =COUNTIF('Add Node'!K:K, "GUI") -> 3 | E5: =COUNTIF('Add Node'!K:K, "CLI") -> 0 | F5: =COUNTIF('Add Node'!L:L, "Yes") -> 0 | G5: =COUNTIFS('Add Node'!A:A, "Y", 'Add Node'!L:L, "No") -> 3 | H5: =COUNTIFS('Add Node'!A:A, "Y", 'Add Node'!L:L, "Yes") -> 0
B6: FM | C6: =SUM(D6,E6) -> 38 | D6: =COUNTIF(FM!S:S, "GUI") -> 38 | E6: =COUNTIF(FM!S:S, "CLI") -> 0 | F6: =COUNTIF(FM!T:T, "Yes") -> 1 | G6: =COUNTIFS(FM!A:A, "Y", FM!T:T, "No") -> 37 | H6: =COUNTIFS(FM!A:A, "Y", FM!T:T, "Yes") -> 1
B7: SHM | C7: =SUM(D7,E7) -> 0 | D7: =COUNTIF(SHM!T:T, "GUI") -> 0 | E7: =COUNTIF(SHM!T:T, "CLI") -> 0 | F7: =COUNTIF(SHM!U:U, "Yes") -> 0 | G7: =COUNTIFS(SHM!A:A, "Y", SHM!U:U, "No") -> 0 | H7: =COUNTIFS(SHM!A:A, "Y", SHM!U:U, "Yes") -> 0
B8: Client Scripting | C8: =SUM(D8,E8) -> 10 | D8: =COUNTIF(ClientScripting!O:O, "GUI") -> 1 | E8: =COUNTIF(ClientScripting!O:O, "CLI") -> 9 | F8: =COUNTIF(ClientScripting!P:P, "Yes") -> 1 | G8: =COUNTIFS(ClientScripting!A:A, "Y", ClientScripting!P:P, "No") -> 9 | H8: =COUNTIFS(ClientScripting!A:A, "Y", ClientScripting!P:P, "Yes") -> 1
B9: Log Viewer | C9: =SUM(D9,E9) -> 9 | D9: =COUNTIF(LV!F:F, "GUI") -> 9 | E9: =COUNTIF(LV!F:F, "CLI") -> 0 | F9: =COUNTIF(LV!G:G, "Yes") -> 0 | G9: =COUNTIFS(LV!A:A, "Y", LV!G:G, "No") -> 9 | H9: =COUNTIFS(LV!A:A, "Y", LV!G:G, "Yes") -> 0
B10: Topology Browser | C10: =SUM(D10,E10) -> 12 | D10: =COUNTIF('Topology Browser'!I:I, "GUI") -> 12 | E10: =COUNTIF('Topology Browser'!I:I, "CLI") -> 0 | F10: =COUNTIF('Topology Browser'!J:J, "Yes") -> 0 | G10: =COUNTIFS('Topology Browser'!A:A, "Y", 'Topology Browser'!J:J, "No") -> 12 | H10: =COUNTIFS('Topology Browser'!A:A, "Y", 'Topology Browser'!J:J, "Yes") -> 0
B11: AMOS | C11: =SUM(D11,E11) -> 18 | D11: =COUNTIF(AMOS!W:W, "GUI") -> 11 | E11: =COUNTIF(AMOS!W:W, "CLI") -> 7 | F11: =COUNTIF(AMOS!X:X, "Yes") -> 2 | G11: =COUNTIFS(AMOS!A:A, "Y", AMOS!X:X, "No") -> 16 | H11: =COUNTIFS(AMOS!A:A, "Y", AMOS!X:X, "Yes") -> 2
B12: Network Explorer | C12: =SUM(D12,E12) -> 16 | D12: =COUNTIF(NetworkExplorer!J:J, "GUI") -> 16 | E12: =COUNTIF(NetworkExplorer!J:J, "CLI") -> 0 | F12: =COUNTIF(NetworkExplorer!K:K, "Yes") -> 0 | G12: =COUNTIFS(NetworkExplorer!A:A, "Y", NetworkExplorer!K:K, "No") -> 16 | H12: =COUNTIFS(NetworkExplorer!A:A, "Y", NetworkExplorer!K:K, "Yes") -> 0
B13: Identity Access Management | C13: =SUM(D13,E13) -> 30 | D13: =COUNTIF(IDAM!M:M, "GUI") -> 30 | E13: =COUNTIF(IDAM!M:M, "CLI") -> 0 | F13: =COUNTIF(IDAM!N:N, "Yes") -> 1 | G13: =COUNTIFS(IDAM!A:A, "Y", IDAM!N:N, "No") -> 29 | H13: =COUNTIFS(IDAM!A:A, "Y", IDAM!N:N, "Yes") -> 1
B14: CM(Add,Synchronize & Delete) | C14: =SUM(D14,E14) -> 3 | D14: =COUNTIF('CM Add and Synchronize Node'!P:P, "GUI") -> 3 | E14: =COUNTIF('CM Add and Synchronize Node'!P:P, "CLI") -> 0 | F14: =COUNTIF('CM Add and Synchronize Node'!Q:Q, "Yes") -> 3 | G14: =COUNTIFS('CM Add and Synchronize Node'!A:A, "Y", 'CM Add and Synchronize Node'!Q:Q, "No") -> 0 | H14: =COUNTIFS('CM Add and Synchronize Node'!A:A, "Y", 'CM Add and Synchronize Node'!Q:Q, "Yes") -> 3
B15: License Control and Monitoring | C15: =SUM(D15,E15) -> 8 | D15: =COUNTIF('License Control and Monitoring'!F:F, "GUI") -> 7 | E15: =COUNTIF('License Control and Monitoring'!F:F, "CLI") -> 1 | F15: =COUNTIF('License Control and Monitoring'!G:G, "Yes") -> 1 | G15: =COUNTIFS('License Control and Monitoring'!A:A, "Y", 'License Control and Monitoring'!G:G, "No") -> 7 | H15: =COUNTIFS('License Control and Monitoring'!A:A, "Y", 'License Control and Monitoring'!G:G, "Yes") -> 1
B16: CMCLI | C16: =SUM(D16,E16) -> 9 | D16: =COUNTIF(CMCLI!Q:Q, "GUI") -> 8 | E16: =COUNTIF(CMCLI!Q:Q, "CLI") -> 1 | F16: =COUNTIF(CMCLI!R:R, "Yes") -> 4 | G16: =COUNTIFS(CMCLI!A:A, "Y", CMCLI!R:R, "No") -> 5 | H16: =COUNTIFS(CMCLI!A:A, "Y", CMCLI!R:R, "Yes") -> 4
B17: Network Health Monitor | C17: =SUM(D17,E17) -> 43 | D17: =COUNTIF(NHM!O:O, "GUI") -> 43 | E17: =COUNTIF(NHM!O:O, "CLI") -> 0 | F17: =COUNTIF(NHM!P:P, "Yes") -> 1 | G17: =COUNTIFS(NHM!A:A, "Y", NHM!P:P, "No") -> 42 | H17: =COUNTIFS(NHM!A:A, "Y", NHM!P:P, "Yes") -> 1
B18: Network Viewer | C18: =SUM(D18,E18) -> 21 | D18: =COUNTIF('Network Viewer'!P:P, "GUI") -> 21 | E18: =COUNTIF('Network Viewer'!P:P, "CLI") -> 0 | F18: =COUNTIF('Network Viewer'!Q:Q, "Yes") -> 1 | G18: =COUNTIFS('Network Viewer'!A:A, "Y", 'Network Viewer'!Q:Q, "No") -> 20 | H18: =COUNTIFS('Network Viewer'!A:A, "Y", 'Network Viewer'!Q:Q, "Yes") -> 1
B19: NHC | C19: =SUM(D19,E19) -> 12 | D19: =COUNTIF(NHC!U:U, "GUI") -> 7 | E19: =COUNTIF(NHC!U:U, "CLI") -> 5 | F19: =COUNTIF(NHC!V:V, "Yes") -> 0 | G19: =COUNTIFS(NHC!A:A, "Y", NHC!V:V, "No") -> 12 | H19: =COUNTIFS(NHC!A:A, "Y", NHC!V:V, "Yes") -> 0
B20: Security PKI | C20: =SUM(D20,E20) -> 13 | D20: =COUNTIF('Security PKI'!W:W, "GUI") -> 6 | E20: =COUNTIF('Security PKI'!W:W, "CLI") -> 7 | F20: =COUNTIF('Security PKI'!X:X, "Yes") -> 1 | G20: =COUNTIFS('Security PKI'!A:A, "Y", 'Security PKI'!X:X, "No") -> 12 | H20: =COUNTIFS('Security PKI'!A:A, "Y", 'Security PKI'!X:X, "Yes") -> 1
B21: Automatic ID assignment | C21: =SUM(D21:E21) -> 4 | D21: =COUNTIF(AutoID!G:G, "GUI") -> 4 | E21: =COUNTIF(AutoID!G:G, "CLI") -> 0 | F21: =COUNTIF(AutoID!H:H, "Yes") -> 0 | G21: =COUNTIFS(AutoID!A:A, "Y", AutoID!H:H, "No") -> 4 | H21: =COUNTIFS(AutoID!A:A, "Y", AutoID!H:H, "Yes") -> 0
B22: Winfiol | C22: =SUM(D22:E22) -> 1 | D22: =COUNTIF(WinFIOL!F:F, "GUI") -> 1 | E22: =COUNTIF(WinFIOL!F:F, "CLI") -> 0 | F22: =COUNTIF(WinFIOL!G:G, "Yes") -> 0 | G22: =COUNTIFS(WinFIOL!A:A, "Y", WinFIOL!G:G, "No") -> 1 | H22: =COUNTIFS(WinFIOL!A:A, "Y", WinFIOL!G:G, "Yes") -> 0
B23: Cell Management | C23: 5 | D23: =COUNTIF('Cell Management'!F:F, "GUI") -> 5 | E23: =COUNTIF('Cell Management'!F:F, "CLI") -> 0 | F23: =COUNTIF('Cell Management'!G:G, "Yes") -> 2 | G23: =COUNTIFS('Cell Management'!A:A, "Y", 'Cell Management'!G:G, "No") -> 3 | H23: =COUNTIFS('Cell Management'!A:A, "Y", 'Cell Management'!G:G, "Yes") -> 2
B24: Parameter Management | C24: =SUM(D24:E24) -> 4 | D24: =COUNTIF('Parameter Management'!I:I, "GUI") -> 4 | E24: =COUNTIF('Parameter Management'!I:I, "CLI") -> 0 | F24: =COUNTIF('Parameter Management'!J:J, "Yes") -> 0 | G24: =COUNTIFS('Parameter Management'!A:A, "Y", 'Parameter Management'!J:J, "No") -> 4 | H24: =COUNTIFS('Parameter Management'!A:A, "Y", 'Parameter Management'!J:J, "Yes") -> 0
B25: AutoProvisioning | C25: =SUM(D25:E25) -> 7 | D25: =COUNTIF('Auto Provisioning'!J:J, "GUI") -> 7 | E25: =COUNTIF('Auto Provisioning'!J:J, "CLI") -> 0 | F25: =COUNTIF('Auto Provisioning'!K:K, "Yes") -> 0 | G25: =COUNTIFS('Auto Provisioning'!A:A, "Y", 'Auto Provisioning'!K:K, "No") -> 7 | H25: =COUNTIFS('Auto Provisioning'!A:A, "Y", 'Auto Provisioning'!K:K, "Yes") -> 0
B26: Release Independence | C26: =SUM(D26:E26) -> 7 | D26: =COUNTIF('Release Independence'!E:E, "GUI") -> 7 | E26: =COUNTIF('Release Independence'!E:E, "CLI") -> 0 | F26: =COUNTIF('Release Independence'!F:F, "Yes") -> 0 | G26: =COUNTIFS('Release Independence'!A:A, "Y", 'Release Independence'!F:F, "No") -> 7 | H26: =COUNTIFS('Release Independence'!A:A, "Y", 'Release Independence'!F:F, "Yes") -> 0
B27: User Management | C27: =SUM(D27:E27) -> 1 | D27: =COUNTIF('User Management'!F:F, "GUI") -> 1 | E27: =COUNTIF('User Management'!F:F, "CLI") -> 0 | F27: =COUNTIF('User Management'!G:G, "Yes") -> 0 | G27: =COUNTIFS('User Management'!A:A, "Y", 'User Management'!G:G, "No") -> 1 | H27: =COUNTIFS('User Management'!A:A, "Y", 'User Management'!G:G, "Yes") -> 0
B28: OPS | C28: =SUM(D28:E28) -> 2 | D28: =COUNTIF(OPS!E:E, "GUI") -> 2 | E28: =COUNTIF(OPS!E:E, "CLI") -> 0 | F28: =COUNTIF(OPS!F:F, "Yes") -> 0 | G28: =COUNTIFS(OPS!A:A, "Y", FMX!F:F, "No") -> 0 | H28: =COUNTIFS(OPS!A:A, "Y", FMX!F:F, "Yes") -> 0
B29: Bulk Configuration | C29: =SUM(D29:E29) -> 2 | D29: =COUNTIF('Bulk Configuration'!G:G, "GUI") -> 2 | E29: =COUNTIF('Bulk Configuration'!G:G, "CLI") -> 0 | F29: =COUNTIF('Bulk Configuration'!H:H, "Yes") -> 0 | G29: =COUNTIFS('Bulk Configuration'!A:A, "Y", 'Bulk Configuration'!H:H, "No") -> 2 | H29: =COUNTIFS('Bulk Configuration'!A:A, "Y", 'Bulk Configuration'!H:H, "Yes") -> 0
B30: High Availability | C30: 1 | D30: =COUNTIF('High Availability'!I:I, "GUI") -> 0 | E30: =COUNTIF('High Availability'!I:I, "CLI") -> 1 | F30: =COUNTIF('High Availability'!J:J, "Yes") -> 0 | G30: =COUNTIFS('High Availability'!A:A, "Y", 'High Availability'!J:J, "No") -> 1 | H30: =COUNTIFS('High Availability'!A:A, "Y", 'High Availability'!J:J, "Yes") -> 0
B31: FMX | C31: =SUM(D31:E31) -> 19 | D31: =COUNTIF(FMX!L:L, "GUI") -> 18 | E31: =COUNTIF(FMX!L:L, "CLI") -> 1 | F31: =COUNTIF(FMX!M:M, "Yes") -> 0 | G31: =COUNTIFS(FMX!A:A, "Y", FMX!M:M, "No") -> 19 | H31: =COUNTIFS(FMX!A:A, "Y", FMX!M:M, "Yes") -> 0
B32: ESM | C32: =SUM(D32:E32) -> 6 | D32: =COUNTIF(ESM!E:E, "GUI") -> 6 | E32: =COUNTIF(ESM!E:E, "CLI") -> 0 | F32: =COUNTIF(ESM!F:F, "Yes") -> 0 | G32: =COUNTIFS(ESM!A:A, "Y", ESM!F:F, "No") -> 6 | H32: =COUNTIFS(ESM!A:A, "Y", ESM!F:F, "Yes") -> 0
B33: PLM | C33: =SUM(D33:E33) -> 1 | D33: =COUNTIF(PLM!G:G, "GUI") -> 1 | E33: =COUNTIF(PLM!G:G, "CLI") -> 0 | F33: =COUNTIF(PLM!H:H, "Yes") -> 0 | G33: =COUNTIFS(PLM!A:A, "Y", PLM!H:H, "No") -> 1 | H33: =COUNTIFS(PLM!A:A, "Y", PLM!H:H, "Yes") -> 0
B34: Configuration Management | C34: =SUM(D34:E34) -> 9 | D34: =COUNTIF('Configuration Management'!N:N, "GUI") -> 0 | E34: =COUNTIF('Configuration Management'!N:N, "CLI") -> 9 | F34: =COUNTIF('Configuration Management'!O:O, "Yes") -> 2 | G34: =COUNTIFS('Configuration Management'!A:A, "Y", 'Configuration Management'!O:O, "No") -> 5 | H34: =COUNTIFS('Configuration Management'!A:A, "Y", 'Configuration Management'!O:O, "Yes") -> 2
B35: NCM | C35: =SUM(D35:E35) -> 1 | D35: =COUNTIF(NCM!E:E, "GUI") -> 1 | E35: =COUNTIF(NCM!E:E, "CLI") -> 0 | F35: =COUNTIF(NCM!F:F, "Yes") -> 0 | G35: =COUNTIFS(NCM!A:A, "Y", NCM!F:F, "No") -> 1 | H35: =COUNTIFS(NCM!A:A, "Y", NCM!F:F, "Yes") -> 0
B36: Total Count Summary | C36: =SUM(C4:C35) -> 381 | D36: =SUM(D4:D34) -> 339 | E36: =SUM(E4:E34) -> 41 | F36: =SUM(F4:F35) -> 20 | G36: =SUM(G4:G35) -> 336 | H36: =SUM(H4:H35) -> 20

Sheet ESM
A1: Execution_Flag | B1: Test Case | C1: Robot_File_Name | D1: Description | E1: Mode | F1: Service affecting | G1: Comment | H1: Node Support Information
A2: Y | B2: ESM-3.1 | C2: GUI-ESM-00-3.1.robot | D2: Create Internal Alert | E2: GUI | F2: No
A3: Y | B3: ESM-3.3 | C3: GUI-ESM-00-3.3.robot | D3: Navigate to Monitoring Dashboards in ESM GUI | E3: GUI | F3: No
A4: Y | B4: ESM-3.4 | C4: GUI-ESM-00-3.4.robot | D4: Navigate to Performance and Optimization dashboards in ESM UI | E4: GUI | F4: No
A5: Y | B5: ESM-3.5 | C5: GUI-ESM-00-3.5.robot | D5: Navigate to Provisioning dashboards in ESM UI | E5: GUI | F5: No
A6: Y | B6: ESM-3.6 | C6: GUI-ESM-00-3.6.robot | D6: Navigate to System dashboards in ESM UI | E6: GUI | F6: No
A7: Y | B7: ESM-3.7 | C7: GUI-ESM-00-3.7.robot | D7: Navigate to Security dashboards in ENM UI | E7: GUI | F7: No

Sheet Add Node
A1: Execution_Flag | B1: Test Case | C1: Node | D1: Nodetype | E1: IP address | F1: UserName | G1: Password | H1: Subnetwork | I1: Robot_File_Name | J1: Description | K1: Mode | L1: Service affecting | M1: Comment | N1: Node Support Information
A2: Y | B2: Node information for with mandatory MeContext | C2: Dummynode1 | D2: BSP | E2: 131.111.111.111 | F2: user123 | G2: test123 | I2: GUI-AddNode-00-3.1.robot | J2: Add a network element, with mandatory MEContext parameter, via UI with ManagedElement as the top root managed object. | K2: GUI | L2: No | N2: Dummy nodes are used for testing hence not applicable
A3: Y | B3: Node information for with optional MeContext | C3: Dummynode2 | D3: RadioNode | E3: 12.21.1.12 | F3: user124 | G3: test124 | I3: GUI-AddNode-00-3.2.robot | J3: Add a network element, with mandatory MEContext parameter, via UI with SubNetwork as the top root managed object | K3: GUI | L3: No
A4: Y | B4: Node and subnetwork information for with mandatory MeContext | C4: Dummynode3 | D4: BSP | E4: 10.10.12.23 | F4: user125 | G4: test125 | H4: TESTNETWORK | I4: GUI-AddNode-00-3.3.robot | J4: Add a network element, with optional MEContext parameter, via UI with ManagedElement as the top root managed object | K4: GUI | L4: No

Sheet SHM
A1: Execution_Flag | B1: Test Case | C1: Node | D1: JobName | E1: DuplicateJobName | F1: Information | G1: BackupName | H1: NodeType | I1: status | J1: ImportFile | K1: Product Number | L1: Product Revision | M1: Package_Name | N1: Host | O1: UserName | P1: Password | Q1: BladeName | R1: Savesearch | S1: CollectionName | T1: Robot_File_Name | U1: TestCase-Description | V1: Mode | W1: Service affecting | X1: Comment | Y1: Node Support Information
A2: Y | B2: SHM-3.1 | C2: BB46 | T2: GUI-SHM-00-3.1.robot | U2: View Software Inventory | V2: GUI | W2: No | Y2: All type of Nodes are supported except vMME(IPv6), Baseband T Node(IPv6), SAPC(IPv6), PicoRBS6402(IPv6), MINI-LINKIndoor,SBG/vSBG,CSCF/vCSCF,MTAS/vMTAS,IPWorks/vIPWorks(IPv6),BGF/vBGF(IPv6),BSP(IPv6),vMRF(IPv6),HSS-FE/vHSS-FE(IPV6),RVNFM , Mini-link-669X, Mini-link-665X, Mini-link6366, Mini-link-CN210, Mini-link-CN510R1, Mini-link-CN510R2, Mini-link-CN810R1, Mini-link-CN810R2
A3: Y | B3: SHM-3.3 | C3: BB46 | T3: GUI-SHM-00-3.3.robot | U3: View Hardware Inventory | V3: GUI | W3: No | Y3: All type of Nodes are supported except vMME, Baseband T Node(IPv6), SAPC, PicoRBS6402(IPv6), MINI-LINKIndoor,CSCF/vCSCF(IPv6),MTAS/vMTAS(IPv6),IPWorks/vIPWorks,BGF/vBGF,BSP(IPv6),vMRF,HSS-FE/vHSS-FE,vSD,vPP,RVNFM,RNFVO,HPE-NFV-Director,vMSC-HC,vMSC, vIP-STP,Mini-link-669X, Mini-link-665X, Mini-link6366, Mini-link-CN210, Mini-link-CN510R1, Mini-link-CN510R2, Mini-link-CN810R1, Mini-link-CN810R2
A4: Y | B4: SHM-3.4 | C4: BB46 | T4: GUI-SHM-00-3.4.robot | U4: View License Inventory | V4: GUI | W4: No | Y4: All type of Nodes are supported except SGSN-MME, vMME, Baseband T Node(IPv6), SAPC, PicoRBS6402,CSCF/vCSCF(IPv6),MTAS/vMTAS(IPv6),IPWorks/vIPWorks,BGF/vBGF,BSP(IPv6),vMRF,HSS-FE/vHSS-FE,vSD,vPP,RVNFM,RNFVO,HPE-NFV-Director, NeLS, vTIF
A5: Y | B5: SHM-3.5 | C5: BB46 | T5: GUI-SHM-00-3.5.robot | U5: View Backup Inventory Inventory | V5: GUI | W5: No | Y5: All type of Nodes are supported except vMME(IPv6), Baseband T Node(IPv6), SAPC, PicoRBS6402(IPv6), MINI-LINKIndoor,JUNIPER-MX, JUNIPER-PTX, JUNIPER-SRX, JUNIPER-vMX, JUNIPER-vSRX,CSCF/vCSCF(IPv6),BGF/vBGF,BSP(IPv6),vMRF, HSS-FE/vHSS-FE(IPv6),RNFVO,HPE-NFV-DirectorMini-link-669X, Mini-link-665X, Mini-link6366, Mini-link-CN210, Mini-link-CN510R1, Mini-link-CN510R2, Mini-link-CN810R1, Mini-link-CN810R2
A6: Y | B6: SHM-3.13 | C6: BB46 | D6: MTAS_Test_Data_Backup | F6: standard | T6: GUI-SHM-00-3.13.robot | U6: Manage Backup for CPP based nodes with shm_Administrator role | V6: GUI | W6: No | Y6: All type of Nodes are supported except vMME, Baseband T Node(IPv6), SAPC, PicoRBS6402(IPv6), MINI-LINKIndoor,JUNIPER-MX, JUNIPER-PTX, JUNIPER-SRX, JUNIPER-vMX, JUNIPER-vSRX,SBG/vSBG(IPv6),CSCF/vCSCF(IPv6),MTAS/vMTAS(IPv6),IPWorks/vIPWorks(IPv6),BGF/vBGF,BSP(IPv6),vMRF, HSS-FE/vHSS-FE(IPv6),RNFVO,HPE-NFV-Director,Mini-link-669X, Mini-link-665X, Mini-link6366, Mini-link-CN210, Mini-link-CN510R1, Mini-link-CN510R2, Mini-link-CN810R1, Mini-link-CN810R2, , MINI-LINK Outdoor(ML-6351, ML-6352, PT-2020, Switch-6391, FrontHaul-6392)
A7: Y | B7: SHM-3.36 | D7: ManagBackup | E7: TestBackup_new | T7: GUI-SHM-00-3.36.robot | U7: Create a new Job from Job Details | V7: GUI | W7: No | X7: Dependent on 3.13 | Y7: All type of Nodes are supported except vMME(IPv6), Baseband T Node(IPv6), SAPC, PicoRBS6402(IPv6),JUNIPER-MX, JUNIPER-PTX, JUNIPER-SRX, JUNIPER-vMX, JUNIPER-vSRX,CSCF/vCSCF(IPv6),IPWorks/vIPWorks(IPv6),BGF/vBGF,BSP(IPv6),vMRF, gNodeBBasebandRadioNode,HSS-FE/vHSS-FE(IPv6),RNFVO,HPE-NFV-DirectorMini-link-669X, Mini-link-665X, Mini-link6366, Mini-link-CN210, Mini-link-CN510R1, Mini-link-CN510R2, Mini-link-CN810R1, Mini-link-CN810R2
A8: Y | B8: SHM-3.2 | C8: CBT01-02-BB6648 | T8: GUI-SHM-00-3.2.robot | U8: View Upgrade Packages on node | V8: GUI | W8: No | Y8: All type of Nodes are supported except vMME(IPv6), Baseband T Node(IPv6), SAPC(IPv6), PicoRBS6402(IPv6), MINI-LINKIndoor,SBG/vSBG,CSCF/vCSCF,MTAS/vMTAS,IPWorks/vIPWorks(IPv6),BGF/vBGF(IPv6),BSP(IPv6),vMRF(IPv6),HSS-FE/vHSS-FE,RVNFM,vMSC,BSC,HLR-FE-BSP,HLR-FE-IS,HLR-FE,vHLR-FE,IP-STP-BSP,IP-STP,MSC-BC-BSP,MSC-BC-IS, MSC-DB-BSP, MSC-DB, vMSC-HC, vMSC, vIP-STP , Mini-link-669X, Mini-link-665X, Mini-link6366, Mini-link-CN210, Mini-link-CN510R1, Mini-link-CN510R2, Mini-link-CN810R1, Mini-link-CN810R2
A9: Y | B9: SHM-3.32 | C9: CBT01-02-BB6648 | T9: GUI-SHM-00-3.32.robot | U9: Export Software Inventory Data | V9: GUI | W9: No | Y9: All type of Nodes are supported except vMME(IPv6), Baseband T Node(IPv6), SAPC, PicoRBS6402(IPv6)CSCF/vCSCF(IPv6),MTAS/vMTAS(IPv6),IPWorks/vIPWorks,BGF/vBGF,BSP,vMRF,gNodeBBasebandRadioNode,HSS-FE/vHSS-FE,RVNFMMini-link-669X, Mini-link-665X, Mini-link6366, Mini-link-CN210, Mini-link-CN510R1, Mini-link-CN510R2, Mini-link-CN810R1, Mini-link-CN810R2, MRS, NeLS
A10: Y | B10: SHM-3.33 | C10: CBT01-02-BB6648 | T10: GUI-SHM-00-3.33.robot | U10: Export Hardware Inventory Data | V10: GUI | W10: No | Y10: All type of Nodes are supported except vMME(IPv6), Baseband T Node(IPv6), SAPC, PicoRBS6402(IPv6),CSCF/vCSCF(IPv6),MTAS/vMTAS(IPv6),IPWorks/vIPWorks,BGF/vBGF,BSP,vMRF,gNodeBBasebandRadioNode,HSS-FE/vHSS-FE,vSD,vPP,RVNFM, vMSC-HC, vMSC, vIP-STP, MRS, NeLS, vTIF
A11: Y | B11: SHM-3.34 | C11: CBT01-02-BB6648 | T11: GUI-SHM-00-3.34.robot | U11: Export License Inventory Data | V11: GUI | W11: No | Y11: All type of Nodes are supported except SGSN-MME, vMME, Baseband T Node, SAPC, PicoRBS6402, CSCF/vCSCF(IPv6),MTAS/vMTAS(IPv6),IPWorks/vIPWorks,BGF/vBGF,BSP,vMRF,Fronthaul6080,gNodeBBasebandRadioNode,HSS-FE/vHSS-FE,vSD,vPP,RVNFM,RNFVO,Fronthaul6020,HPE-NFV-Director, MRS, NeLS, vTIF
A12: Y | B12: SHM-3.19 | C12: BB46 | D12: AGATJOB_restore_backup | T12: GUI-SHM-00-3.19.robot | U12: Restore Backup existing on Node | V12: GUI | W12: Yes | Y12: All type of Nodes are supported except vMME(IPv6), Baseband T Node(IPv6), SAPC, PicoRBS6402(IPv6),JUNIPER-MX, JUNIPER-PTX, JUNIPER-SRX, JUNIPER-vMX, JUNIPER-vSRX,SBG/vSBG(IPv6),CSCF/vCSCF(IPv6),MTAS/vMTAS(IPv6),IPWorks/vIPWorks(IPv6),BGF/vBGF,RNFVO, HSS-FE/vHSS-FE(IPv6),RNFVO,RBS,RNC,HPE-NFV-Director,BSC,HLR-FE-BSP,HLR-FE-IS,HLR-FE,vHLR-FE,IP-STP-BSP,IP-STP,MSC-BC-BSP,MSC-BC-IS, MSC-DB-BSP, MSC-DB, vMSC-HC, vMSC, vIP-STP, MINI-LINK Outdoor(ML-6351, ML-6352, PT-2020, Switch-6391, FrontHaul-6392)
A13: Y | B13: SHM-3.24 | C13: BB46 | D13: TestBackup | T13: GUI-SHM-00-3.24.robot | U13: Delete Job | V13: GUI | W13: No | Y13: All type of Nodes are supported except vMME(IPv6), Baseband T Node(IPv6), SAPC, PicoRBS6402(IPv6),JUNIPER-MX, JUNIPER-PTX, JUNIPER-SRX, JUNIPER-vMX, JUNIPER-vSRX,CSCF/vCSCF(IPv6),MTAS/vMTAS(IPv6),IPWorks/vIPWorks,BGF/vBGF,BSP(IPv6),vMRF,HSS-FE/vHSS-FE(IPv6)
A14: Y | B14: SHM-3.12 | C14: BB46 | T14: GUI-SHM-00-3.12A.robot | U14: SHM View Key Files | V14: GUI | W14: No
A15: Y | B15: SHM-3.37 | C15: BB46 | D15: Housekeeping_job_test | T15: GUI-SHM-00-3.37.robot | U15: Housekeeping of Backups for ECIM based nodes with Shm_Administrator role | V15: GUI | W15: No | Y15: All type of Nodes are supported except MGW,vMME,Baseband T Node(IPv6),SAPC,PicoRBS6402(IPv6), MINI-LINKIndoor,JUNIPER-MX, JUNIPER-PTX, JUNIPER-SRX, JUNIPER-vMX, JUNIPER-Vsrx,CSCF/vCSCF(IPv6),MTAS/vMTAS(IPv6),IPWorks/vIPWorks,BGF/vBGF,BSP,vMRF,HSS-FE/vHSS-FE(IPv6),RNFVO,HPE-NFV-Director,BSC,HLR-FE-BSP,HLR-FE-IS,HLR-FE,vHLR-FE,IP-STP-BSP,IP-STP,MSC-BC-BSP,MSC-BC-IS, MSC-DB-BSP, MSC-DB, vMSC-HC, vMSC, vIP-STPMini-link-669X, Mini-link-665X, Mini-link6366, Mini-link-CN210, Mini-link-CN510R1, Mini-link-CN510R2, Mini-link-CN810R1, Mini-link-CN810R2
A16: Y | B16: GUI-SHM-3.23 | C16: BB40 | D16: Test_Node_Backup | F16: Creation of Node backup | G16: Test_Backup | H16: ECIM | T16: GUI-SHM-00-3.23.robot | U16: Create Node backup (CPP/ECIM) | V16: GUI | W16: No
A17: Y | B17: GUI-SHM-4.1 | C17: BB46 | F17: RadioNode2 | H17: ECIM | T17: GUI-SHM-00-4.1.robot | U17: View software Inventory from CLI (CPP/ECIM) | V17: GUI | W17: No
A18: Y | B18: GUI-SHM-4.2 | C18: BB46 | F18: RadioNode2 | H18: ECIM | T18: GUI-SHM-00-4.2.robot | U18: View Hardware Inventory from CLI (CPP/ECIM) | V18: GUI | W18: No
A19: Y | B19: GUI-SHM-4.3 | C19: BB46 | H19: ECIM | T19: GUI-SHM-00-4.3.robot | U19: View Lincense Inventory from CLI (CPP/ECIM) | V19: GUI | W19: No
A20: Y | B20: GUI-SHM-4.4 | C20: BB46 | H20: ECIM | T20: GUI-SHM-00-4.4.robot | U20: View Backup Inventory from CLI (CPP/ECIM) | V20: GUI | W20: No
A21: Y | B21: GUI-SHM-3.28 | D21: SHM_Node_Backup | T21: GUI-SHM-00-3.28.robot | U21: View Inventory Summary (CPP/ECIM) | V21: GUI | W21: No | X21: Dependent on 3.23
A22: Y | B22: GUI-SHM-3.25 | C22: BB40 | D22: Delete_Backup_Job | G22: Test_Backup | T22: GUI-SHM-03-3.25.robot | U22: Delete software backup | V22: GUI | W22: No | X22: Dependent on 3.28 and 3.23
A23: Y | B23: GUI-SHM-4.11 | C23: CBT01-02-BB6648 | D23: Test_Node_Backup_CLI | G23: Test_Backup | H23: ECIM | I23: Immediate | R23: save_search | S23: collection_name | T23: GUI-SHM-00-4.11.robot | U23: backup job from CLI (CPP/ECIM) (Please read the node in status column) | V23: GUI | W23: No
A24: Y | B24: GUI-SHM-4.8 | C24: BB46 | D24: Test_Node_Backup_JOB_CLI | G24: Test_Backup | H24: ECIM | I24: Schedule | R24: shmsavesearch | S24: collection_name | T24: GUI-SHM-00-4.8.robot | U24: backup job from CLI (CPP/ECIM) (Please read the node in status column) | V24: GUI | W24: No
A25: Y | B25: GUI-SHM-3.35 | C25: LTE04dg2ERBS00001 | D25: Test_Backup | F25: Creation of Node backup | G25: TestNode_ECIM | T25: GUI-SHM-00-3.35.robot | U25: Duplicate backup (ECIM) | V25: GUI | W25: No
A26: Y | B26: GUI-SHM-3.12 | J26: key.zip | T26: GUI-SHM-00-3.12B.robot | U26: Import License Key files | V26: GUI | W26: No
A27: Y | B27: GUI-SHM-4.15 | C27: BB46 | K27: CXP9024418/6 | L27: R80G27 | T27: GUI-SHM-00-4.15.robot | U27: View Upgrade Packages on a Node from CLI | V27: GUI | W27: No
A28: Y | B28: GUI-SHM-4.7 | C28: BB46 | T28: GUI-SHM-00-4.7.robot | U28: Delete Upgrade Packages for nodes from CLI | V28: GUI | W28: Yes
A29: Y | B29: GUI-SHM-3.21 | M29: Software_packagename | T29: GUI-SHM-00-3.21.robot | U29: Delete Software Packages | V29: GUI | W29: No
A30: Y | B30: GUI-SHM-3.29 | C30: BB46 | T30: GUI-SHM-00-3.29.robot | U30: Internal Alarm for any Job Failure | V30: GUI | W30: No
A31: Y | B31: GUI-SHM-3.30 | C31: LTE06ERBS00001 | F31: /ericsson/pib-scripts/etc/ | H31: ERBS | N31: 131.160.99.68 | O31: root | P31: 123shroot | Q31: svc-1-smrsserv | T31: CLI-SHM-00-3.30.robot | U31: Housekeeping of Backup files stored in SMRS | V31: CLI | W31: Yes
A32: Y | B32: SHM_MasterGAT_4.9 | C32: BB46 | T32: ENM05.robot | U32: Activation of unlock from cli for nodes | V32: CLI | W32: Yes | X32: Python based | Y32: All type of Nodes are supported except MGW,Baseband Radio node,SGSN-MME,vMME , Baseband T Node , SAPC, Pico RBS6402, MINI-LINK Indoor(Mini-link-TN,Mini-link-LH),Router6672,JUNIPER-MX, JUNIPER-PTX, JUNIPER-SRX, JUNIPER-vMX, JUNIPER-vSRX,HSS-FE/vHSS-FE,vSD,vPP,RVNFM,Router6x71,RNFVO,Fronthaul6020,VTFRadioNode,Router6274,5GRadioNode,Router6273,HPE-NFV-Director,BSC,HLR-FE-BSP,HLR-FE-IS,HLR-FE,vHLR-FE,IP-STP-BSP,IP-STP,MSC-BC-BSP,MSC-BC-IS, MSC-DB-BSP, MSC-DB, vMSC-HC, vMSC, vIP-STP ,Mini-link-669X, Mini-link-665X, Mini-link6366, Mini-link-CN210, Mini-link-CN510R1, Mini-link-CN510R2, Mini-link-CN810R1, Mini-link-CN810R2, MINI-LINK Outdoor(ML-6351, ML-6352, PT-2020, Switch-6391, FrontHaul-6392), NeLS, vTIF
A33: Y | B33: SHM_MasterGAT_4.5 | C33: BB46 | T33: ENM14.robot | U33: Import Software Packages from CLI | V33: CLI | W33: Yes | X33: Python based | Y33: All type of Nodes are supported except MGW,vMME,Baseband T Node(IPv6),SAPC,PicoRBS6402(IPv6), MINI-LINKIndoor,JUNIPER-MX, JUNIPER-PTX, JUNIPER-SRX, JUNIPER-vMX, JUNIPER-Vsrx,SBG/vSBG(IPv6),CSCF/vCSCF,MTAS/vMTAS(IPv6),IPWorks/vIPWorks,BGF/vBGF,BSP(IPv6),vMRF,HSS-FE/vHSS-FE(IPv6), ,HPE-NFV-Director,BSC,HLR-FE-BSP,HLR-FE-IS,HLR-FE,vHLR-FE,IP-STP-BSP,IP-STP,MSC-BC-BSP,MSC-BC-IS, MSC-DB-BSP, MSC-DB, vMSC-HC, vMSC, vIP-STP,Mini-link-669X, Mini-link-665X, Mini-link6366, Mini-link-CN210, Mini-link-CN510R1, Mini-link-CN510R2, Mini-link-CN810R1, Mini-link-CN810R2, MINI-LINK Outdoor(ML-6351, ML-6352, PT-2020, Switch-6391, FrontHaul-6392),NeLS
A34: Y | B34: SHM_MasterGAT_4.6 | C34: BB46 | T34: ENM13.robot | U34: Import_License_Key_Files_from_CLI | V34: CLI | W34: Yes | X34: Python based | Y34: All type of Nodes are supported except MGW,vMME,Baseband T Node(IPv6),SAPC,PicoRBS6402,MINI-LINKIndoor,JUNIPER-MX, JUNIPER-PTX, JUNIPER-SRX, JUNIPER-vMX, JUNIPER-Vsrx, SBG/vSBG(IPv6),CSCF/vCSCF(IPv6),MTAS/vMTAS(IPv6),IPWorks/vIPWorks,BGF/vBGF,BSP,vMRF,Fronthaul6080,HSS-FE/vHSS-FE,vSD,vPP,RVNFM,RNFVO,Fronthaul6020,HPE-NFV-Director,Mini-link-669X, Mini-link-665X, Mini-link6366, Mini-link-CN210, Mini-link-CN510R1, Mini-link-CN510R2, Mini-link-CN810R1, Mini-link-CN810R2, MINI-LINK Outdoor(ML-6351, ML-6352, PT-2020, Switch-6391, FrontHaul-6392), NeLS, vTIF
A35: Y | B35: GUI-SHM-3.6 | T35: GUI-SHM-00-3.6.robot | U35: Import and View Software Packages | V35: GUI | W35: No
A36: Y | B36: SHM_MasterGAT_4.13 | T36: GUI-SHM-00-4.13.robot | U36: View Job status from CLI | V36: GUI | W36: No | Y36: All type of Nodes are supported except MGW,vMME(IPV6), Baseband T Node , SAPC, Pico RBS6402, MINI-LINK Indoor(Mini-link-TN,Mini-link-LH),Router6672,JUNIPER-MX, JUNIPER-PTX, JUNIPER-SRX, JUNIPER-vMX, JUNIPER-vSRX,SBG/vSBG(IPv6),CSCF/vCSCF(IPv6),MTAS/vMTAS(IPv6),IPWorks/vIPWorks,BGF/vBGF,BSP(IPv6),vMRF,Router6675,HSS-FE/vHSS-FE(IPv6),RVNFM,RNFVO,,HPE-NFV-Director,BSC,HLR-FE-BSP,HLR-FE-IS,HLR-FE,vHLR-FE,IP-STP-BSP,IP-STP,MSC-BC-BSP,MSC-BC-IS, MSC-DB-BSP, MSC-DB, vMSC-HC, vMSC, vIP-STP ,Mini-link-669X, Mini-link-665X, Mini-link6366, Mini-link-CN210, Mini-link-CN510R1, Mini-link-CN510R2, Mini-link-CN810R1, Mini-link-CN810R2, MINI-LINK Outdoor(ML-6351, ML-6352, PT-2020, Switch-6391, FrontHaul-6392),NeLS
A37: Y | B37: SHM_MasterGAT_3.27 | T37: GUI-SHM-00-3.27.robot | U37: Add Job Comments with Shm_Administrator role | V37: GUI | W37: No | Y37: All type of Nodes are supported except vMME(IPv6), Baseband T Node(IPv6), SAPC, PicoRBS6402(IPv6),JUNIPER-MX, JUNIPER-PTX, JUNIPER-SRX, JUNIPER-vMX, JUNIPER-vSRX, CSCF/vCSCF(IPv6),IPWorks/vIPWorks(IPv6),BGF/vBGF,BSP,vMRF,HSS-FE/vHSS-FE(IPv6)
A38: Y | B38: SHM_MasterGAT_3.26 | T38: GUI-SHM-00-3.26.robot | U38: Export Job Logs with Shm_Administrator role | V38: GUI | W38: No | Y38: All type of Nodes are supported except vMME(IPv6), Baseband T Node(IPv6), SAPC, PicoRBS6402(IPv6),JUNIPER-MX, JUNIPER-PTX, JUNIPER-SRX, JUNIPER-vMX, JUNIPER-vSRX,CSCF/vCSCF(IPv6),IPWorks/vIPWorks(IPv6),BGF/vBGF,BSP,vMRF,HSS-FE/vHSS-FE(IPv6)Mini-link-669X, Mini-link-665X, Mini-link6366, Mini-link-CN210, Mini-link-CN510R1, Mini-link-CN510R2, Mini-link-CN810R1, Mini-link-CN810R2

Sheet CMCLI
A1: Execution_Flag | B1: Test Case | C1: Node | D1: NodeType | E1: UserLevel | F1: EnmUrl | G1: Host | H1: UserName | I1: Password | J1: CERT Name | K1: Credentials File Name | L1: FileName | M1: FileType | N1: FDN | O1: Robot_File_Name | P1: Description | Q1: Mode | R1: Service affecting | S1: Comment | T1: Node Support Information
A2: Y | B2: Get and Set Attributes on a Managed Object on NE | C2: BB46 | E2: "TEST" | O2: GUI-CMCLI-00-4.1.robot | P2: Cmedit Get and set [ Update NE attributes from CLI] | Q2: GUI | R2: Yes | S2: Supported by all type of nodes as per GAT document
A3: Y | B3: Create and Delete Managed Objects on NE | C3: BB46 | O3: GUI-CMCLI-00-4.2.robot | P3: Cmedit Create & Delete Commands [ Update NE attributes from CLI] | Q3: GUI | R3: Yes
A4: Y | B4: GUI-CMCLI-8.1 | C4: CBT01-02-BB6648 | D4: ECIM | O4: GUI-CMCLI-00-8.1.robot | P4: Execute a modelled action on a Managed Object | Q4: GUI | R4: No
A5: Y | B5: Bulk Import REST NBI Import file into Live Configuration | F5: enm1.lmf.ericsson.se | G5: 131.160.99.68 | H5: root | I5: 123shroot | J5: ENM_PKI_Root_CA.pem | K5: enmcred.txt | L5: BB46_Node_Userlevel_update.txt | N5: SubNetwork=RadioNode1,ManagedElement=BB46 | O5: CLI-CMCLI-00-9.1.robot | P5: Bulk Import REST NBI Import file into Live Configuration | Q5: CLI | R5: Yes
A6: Y | B6: Import File into Live Configuration | L6: Node_UserLabel_update.txt | M6: dynamic | N6: SubNetwork=RadioNode1,ManagedElement=BB46 | O6: GUI-CMCLI-00-6.1.robot | P6: Import File into Live Configuration | Q6: GUI | R6: Yes
A7: Y | B7: Export CM data in Dynamic format with and without user defined filter and download the export file | L7: UserDefinedFilter.txt | O7: GUI-CMCLI-00-5.2.robot | P7: Export CM data in Dynamic format with and without user defined filter and download the export file | Q7: GUI | R7: No
A8: Y | B8: CMCLI_MasterGAT_3.1 | O8: GUI-CMCLI-00-3.1.robot | P8: Read Modelled Data of a Managed Object | Q8: GUI | R8: No | S8: Supported by all type of nodes as per GAT document
A9: Y | B9: CMCLI_MasterGAT_5.1 | O9: GUI-CMCLI-00-5.1.robot | P9: Export CM data in 3GPP format with and without user defined filter and download the export file | Q9: GUI | R9: No
A10: Y | B10: CMCLI-Custom_01 | O10: GUI-CMCLI-00-Custom-01.robot | P10: Read non-persistent attributes | Q10: GUI | R10: No

Sheet ClientScripting
A1: Execution_Flag | B1: Test Case | C1: Hostname | D1: UserName | E1: Password | F1: Admin_Username | G1: Admin_Password | H1: Client_Host | I1: Client_Username | J1: Client_Password | K1: CERT Name | L1: Credentials File Name | M1: Robot_File_Name | N1: Description | O1: Mode | P1: Service affecting | Q1: Comment | R1: Node Support Information
A2: Y | B2: Host details | C2: 131.160.99.68 | D2: root | E2: 123shroot | F2: Administrator | G2: 123Shroot123Shroot | H2: scp-1-scripting | I2: administrator | J2: TestPassw0rd
A3: Y | B3: CLI-ClientScripting-3-2 | C3: 131.160.99.68 | D3: root | E3: 123shroot | H3: 131.160.100.40 | I3: root | J3: 12shroot | M3: CLI-ClientScripting-00-3.2.robot | N3: Install ENM Scripting Support Library | O3: CLI | P3: Yes | Q3: Dependent On GUI-ClientScripting-00-3.1.robot | R3: Node independent
A4: Y | B4: CLI-ClientScripting-3-7 | C4: 131.160.99.68 | D4: root | E4: 123shroot | H4: scp-1-scripting | I4: administrator | J4: TestPassw0rd | K4: ENM_PKI_Root_CA.pem | L4: enmcred.txt | M4: CLI-ClientScripting-00-3.7.robot | N4: Use ENM Scripting Support Library to execute a simple command using command API and using SSO token for authentication | O4: CLI | P4: No
A5: Y | B5: CLI-ClientScripting-3.3 | M5: CLI-ClientScripting-00-3.3.robot | N5: Use ENM Scripting Support Library to execute a simple command using terminal API | O5: CLI | P5: No
A6: Y | B6: CLI-ClientScripting-3.4 | M6: CLI-ClientScripting-00-3.4.robot | N6: Use ENM Scripting Support Library to execute a simple command using command API | O6: CLI | P6: No
A7: Y | B7: CLI-ClientScripting-3.5 | M7: CLI-ClientScripting-00-3.5.robot | N7: Use ENM Scripting Support Library to execute a command that uploads a file | O7: CLI | P7: No
A8: Y | B8: CLI-ClientScripting-3.6 | M8: CLI-ClientScripting-00-3.6.robot | N8: Use ENM Scripting Support Library to execute a command that downloads a file | O8: CLI | P8: No
A9: Y | B9: CLI-ClientScripting-3.8 | M9: CLI-ClientScripting-00-3.8.robot | N9: Use ENM Scripting Support Library to execute a simple command using command API from VM | O9: CLI | P9: No
A10: Y | B10: CLI-ClientScripting-3.9 | M10: CLI-ClientScripting-00-3.9.robot | N10: Use ENM Scripting Support Library to execute a command that uploads a file from VM | O10: CLI | P10: No
A11: Y | B11: CLI-ClientScripting-3.10 | M11: CLI-ClientScripting-00-3.10.robot | N11: Use ENM Scripting Support Library to execute a command that downloads a file from VM | O11: CLI | P11: No
A12: Y | B12: GUI-ClientScripting-3.1 | M12: GUI-ClientScripting-00-3.1.robot | N12: Download ENM Scripting Support Library | O12: GUI | P12: No

Sheet Configuration Management
A1: Execution_Flag | B1: Test Case | C1: Node | D1: EnmUrl | E1: Host | F1: UserName | G1: Password | H1: CERT Name | I1: Credentials File Name | J1: FileName | K1: FileType | L1: Robot_File_Name | M1: Description | N1: Mode | O1: Service affecting | P1: Comment | Q1: Node Support Information
A2: Y | B2: Configuration Root Request | D2: enm1.lmf.ericsson.se | E2: 131.160.99.68 | F2: root | G2: 123shroot | H2: ENM_PKI_Root_CA.pem | I2: enmcred.txt | L2: CLI-ConfigurationManagement-00-3.1.robot | M2: Configuration Root Request | N2: CLI | O2: No
A3: Y | B3: Bulk Root Request | D3: enm1.lmf.ericsson.se | E3: 131.160.99.68 | F3: root | G3: 123shroot | H3: ENM_PKI_Root_CA.pem | I3: enmcred.txt | L3: CLI-ConfigurationManagement-00-4.1.robot | M3: Bulk Root Request | N3: CLI | O3: No
A4: Y | B4: CM Events NBI non-persistent filter queries | C4: BB46 | D4: enm1.lmf.ericsson.se | E4: 131.160.99.68 | F4: root | G4: 123shroot | H4: ENM_PKI_Root_CA.pem | I4: enmcred.txt | L4: CLI-ConfigurationManagement-00-9.1.robot | M4: CM Events NBI non-persistent filter queries | N4: CLI | O4: No
A5: Y | B5: CM Events NBI Persistent filter queries | D5: enm1.lmf.ericsson.se | E5: 131.160.99.68 | F5: root | G5: 123shroot | H5: ENM_PKI_Root_CA.pem | I5: enmcred.txt | J5: CmNodeHeartbeatSupervision_update_filter.json | L5: CLI-ConfigurationManagement-00-9.2.robot | M5: CM Events NBI Persistent filter queries | N5: CLI | O5: No
A6: Y | B6: Import Dynamic file into live configuration using continue on error | D6: enm1.lmf.ericsson.se | E6: 131.160.99.68 | F6: root | G6: 123shroot | H6: ENM_PKI_Root_CA.pem | I6: enmcred.txt | J6: BB46_Userlevel_update.txt | L6: CLI-ConfigurationManagement-00-5.4.robot | M6: Import Dynamic file into live configuration using continue on error | N6: CLI | O6: Yes | P6: SA depending on imported file content
A7: Y | B7: Revocation for Import command | D7: enm1.lmf.ericsson.se | E7: 131.160.99.68 | F7: root | G7: 123shroot | H7: ENM_PKI_Root_CA.pem | I7: enmcred.txt | J7: revocation.txt | L7: CLI-ConfigurationManagement-00-3.6.robot | M7: Revocation for Import command | N7: CLI | O7: Yes | P7: SA depending on imported file content
A8: N | B8: Export CM data with a User Defined Filter and download | D8: enm1.lmf.ericsson.se | E8: 131.160.99.68 | F8: root | G8: 123shroot | H8: ENM_PKI_Root_CA.pem | I8: enmcred.txt | K8: dynamic | L8: CLI-ConfigurationManagement-00-6.2.robot | M8: Export CM data with a User Defined Filter and download | N8: CLI | O8: No
A9: N | B9: Export CM data in 3GPP format or in Dynamic file format, download export file and remove export job | D9: enm1.lmf.ericsson.se | E9: 131.160.99.68 | F9: root | G9: 123shroot | H9: ENM_PKI_Root_CA.pem | I9: enmcred.txt | K9: dynamic | L9: CLI-ConfigurationManagement-00-6.1.robot | M9: Export CM data in 3GPP format or in Dynamic file format, download export file and remove export job | N9: CLI | O9: No
A10: Y | B10: Get Filter Types | D10: enm1.lmf.ericsson.se | E10: 131.160.99.68 | F10: root | G10: 123shroot | H10: ENM_PKI_Root_CA.pem | I10: enmcred.txt | L10: CLI-ConfigurationManagement-00-7.1.robot | M10: Get Filter Types | N10: CLI | O10: No

Sheet Bulk Configuration
A1: Execution_Flag | B1: Test Case | C1: JobName | D1: ImportFile | E1: Robot_File_Name | F1: Description | G1: Mode | H1: Service affecting | I1: Comment | J1: Node Support Information
A2: Y | B2: GUI-BC-3.1 | C2: Test_hello | D2: BB46.txt | E2: GUI-BC-00-3.1.robot | F2: Create Job & Validate | G2: GUI | H2: NO | I2: Need to import configuration.txt file of the node.
A3: Y | B3: GUI-BC-3.2 | C3: Test_hello | E3: GUI-BC-01-3.2.robot | F3: Job Details and Execute Job | G3: GUI | H3: NO

Sheet Security PKI
A1: Execution_Flag | B1: Test Case | C1: Node | D1: ProfileName | E1: Trusted_CA | F1: EntityName | G1: Entity_Profile | H1: Key_Generation_Algorithm | I1: Common_name | J1: Country_name | K1: Organization | L1: Organization_unit | M1: Hostname | N1: UserName | O1: Password | P1: Bladeinformation | Q1: BladeName | R1: BladeUserName | S1: BladePassword | T1: BladeRootPassword | U1: Robot_File_Name | V1: Description | W1: Mode | X1: Service affecting | Y1: Comment | Z1: Node Support Information
A2: Y | B2: SecurityPKI-7.5 | D2: TestProfile | E2: ENM_External_Entity_CA | U2: GUI-SecurityPKI-00-7.5.robot | V2: Insert new correct trust profile | W2: GUI | X2: No
A3: Y | B3: SecurityPKI-7.13 | F3: TestProfile | G3: ENM_PKI_Root_CA_EP | H3: RSA-2048 | I3: Test | J3: US | K3: Ericsson | L3: Kol | U3: GUI-SecurityPKI-00-7.13.robot | V3: Insert new correct ca entity | W3: GUI | X3: No
A4: Y | B4: SecurityPKI_MasterGAT_4.9 | U4: CLI-SecurityPKI-00-4.9.robot | V4: Southbound HTTP load-balancer base implementation and deployment - IPv4 Ports (This test is apllicable only to Physical ENM) | W4: CLI | X4: No | Z4: Node independent
A5: Y | B5: SecurityPKI_MasterGAT_5.2 | U5: GUI-SecurityPKI-00-5.2.robot | V5: Get Security Level status all NetworkElements | W5: GUI | X5: No | Z5: MRS
A6: Y | B6: SecurityPKI_MasterGAT_6.5 | U6: GUI-SecurityPKI-00-6.5.robot | V6: Credm Web CLI to list existing Services and Certificates | W6: GUI | X6: No | Z6: Node independent
A7: Y | B7: SecurityPKI_MasterGAT_6.6 | U7: GUI-SecurityPKI-00-6.6.robot | V7: Credm Web CLI to list existing Services and Certificates | W7: GUI | X7: No | Z7: Node independent
A8: Y | B8: Host details | M8: 131.160.99.68 | N8: root | O8: 123shroot | P8: SVC-1 | Q8: SCP-1 | R8: litp-admin | S8: 123shroot | T8: 123shroot | U8: CLI-SecurityPKI-00-4.9.robot | V8: Southbound HTTP load-balancer base implementation and deployment - IPv4 Ports (This test is apllicable only to Physical ENM) | W8: CLI | X8: NO | Z8: Node Independent
A9: Y | B9: SecurityPKI_MasterGAT_8.1 | C9: BB46 | U9: ENM06.robot | V9: Node Security commands to get nodes credentials with password encrypted - positive scenarios | W9: CLI | X9: No | Y9: Python based | Z9: CPP,Radio Node,vSAPC,MSRBS V1,FH6080,SBG,CSCF,MTAS,RadioT Node,BSP,DSC,Router6672/75/6274/6x71/6273,(v)IPWorks,VTFRadio Node,5GRadioNode,vPP,HLR-FE/MSC,MRS,UDM/SC/EDA,vTIF,ESC/SCU,FH6020
A10: Y | B10: SecurityPKI_MasterGAT_8.2 | C10: BB46 | U10: ENM07.robot | V10: Node Security commands to get nodes credentials with password encrypted - negative scenarios | W10: CLI | X10: No | Y10: Python based | Z10: CPP,Radio Node,vSAPC,FH6080,SBG,CSCF,MTAS,RadioT Node,VTFRadio Node,5GRadioNode,vPP,HLR-FE/MSC,MRS,UDM/SC/EDA,vTIF,ESC/SCU,vRC,FH6020
A11: Y | B11: SecurityPKI_MasterGAT_8.3 | C11: BB46 | U11: ENM08.robot | V11: Node Security commands to get nodes credentials with password in plain text - positive scenarios | W11: CLI | X11: No | Y11: Python based | Z11: CPP,Radio Node,vSAPC,EPG/VEPG,FH6080,SBG,CSCF,MTAS,RadioT Node,BSP,DSC,Router6672/75/6274/6x71/6273,(v)IPWorks,VTFRadio Node,5GRadioNode,vPP,HLR-FE/MSC,MRS,UDM/SC/EDA,vTIF,ESC/SCU,vRC,FH6020
A12: Y | B12: SecurityPKI_MasterGAT_8.4 | C12: BB46 | U12: ENM09.robot | V12: Node Security commands to get nodes credentials with password in plain text - negative scenarios | W12: CLI | X12: No | Y12: Python based | Z12: CPP,Radio Node,vSAPC,EPG/VEPG,FH6080,SBG,CSCF,MTAS,RadioT Node,VTFRadio Node,5GRadioNode,vPP,HLR-FE/MSC,MRS,UDM/SC/EDA,vTIF,ESC/SCU,vRC,FH6020
A13: Y | B13: SecurityPKI_MasterGAT_10.1 | C13: BB46 | U13: ENM10.robot | V13: Set ciphers and Get ciphers on Com/ECIM nodes | W13: CLI | X13: Yes | Y13: Python based | Z13: Radio Node,Router6672/75/6274/6x71/6273,vTIF,,FH6020
A14: Y | B14: SecurityPKI_MasterGAT_14.2 | C14: BB46 | U14: ENM11.robot | V14: Distribution of LAAD files on the node | W14: GUI | X14: No | Y14: Python based | Z14: MRS

Sheet Network Viewer
A1: Execution_Flag | B1: Test Case | C1: Node | D1: Nodetype | E1: IP address | F1: Security Pass | G1: Latitude | H1: Longitude | I1: Security Password | J1: Node2 | K1: Link Name | L1: Link Desc | M1: Collection Name | N1: Robot_File_Name | O1: Description | P1: Mode | Q1: Service affecting | R1: Comment | S1: Node Support Information
A2: Y | B2: NetworkViewer-MAsterGAT-3.7 | C2: BB46 | N2: GUI-NetworkViewer-00-3.7.robot | O2: Rendering of the alarm state of the node on geographical and logical view | P2: GUI | Q2: No | S2: Supported by all type of nodes as per GAT document
A3: Y | B3: NetworkViewer-MAsterGAT-3.8 | C3: Testnode200 | D3: RadioNode | E3: 90.121.121.103 | F3: abc | I3: abc | N3: GUI-NetworkViewer-00-3.8.robot | O3: Invocation of the Add Node application on geographical view | P3: GUI | Q3: No
A4: Y | B4: NetworkViewer-MAsterGAT-3.9 | C4: Testnode111 | D4: RadioNode | E4: 90.121.121.101 | F4: abc | I4: abc | N4: GUI-NetworkViewer-00-3.9.robot | O4: Invocation of the Delete Node operation on geographical and logical view | P4: GUI | Q4: No
A5: Y | B5: NetworkViewer-MAsterGAT-3.10 | C5: BB46 | N5: GUI-NetworkViewer-00-3.10.robot | O5: Invocation of the Alarm Monitor on selected node on geographical and logical view | P5: GUI | Q5: No
A6: Y | B6: NetworkViewer-MAsterGAT-3.11 | C6: BB46 | N6: GUI-NetworkViewer-00-3.11.robot | O6: Invocation of the Topology Browser application on geographical and logical view | P6: GUI | Q6: No
A7: Y | B7: NetworkViewer-MAsterGAT-3.12 | C7: BB46 | N7: GUI-NetworkViewer-00-3.12.robot | O7: Invocation of the Element Manager application on geographical and logical view | P7: GUI | Q7: No
A8: Y | B8: NetworkViewer-MAsterGAT-3.18 | C8: Testnode521 | D8: RadioNode | E8: 90.121.121.102 | F8: abc | I8: abc | N8: GUI-NetworkViewer-00-3.18.robot | O8: Invocation of the Add Node application in Custom Topology tree | P8: GUI | Q8: No
A9: Y | B9: NetworkViewer-MAsterGAT-3.19 | C9: Testnode222 | D9: RadioNode | E9: 90.121.121.100 | F9: abc | I9: abc | N9: GUI-NetworkViewer-00-3.19.robot | O9: Invocation of the Delete Node operation in Custom Topology tree | P9: GUI | Q9: No
A10: Y | B10: NetworkViewer-MAsterGAT-3.30 | C10: Testnode | N10: GUI-NetworkViewer-00-3.30.robot | O10: Delete all links of a node | P10: GUI | Q10: Yes | S10: Supported only by Normalized Network Elements as per GAT document
A11: Y | B11: NetworkViewer-MAsterGAT-3.14 | C11: BB46 | N11: GUI-NetworkViewer-00-3.14.robot | O11: Invocation of the Alarm Monitor for related nodes on geographical and logical view | P11: GUI | Q11: No
A12: Y | B12: Create a link | C12: BB46 | J12: BB40 | K12: Test_Link | L12: CTAF_TEST_LINK | N12: GUI-NetworkViewer-00-3.26.robot | O12: Create a link | P12: GUI | Q12: No
A13: Y | B13: Delete a link | C13: BB46 | J13: BB40 | K13: Test_Link | L13: CTAF_TEST_LINK | N13: GUI-NetworkViewer-00-3.29.robot | O13: Delete a link | P13: GUI | Q13: No | R13: Dependent on 3.26
A14: Y | B14: Rendering of the applied leaf selection on map view for custom topology tree view | C14: BB46 | M14: GAT_Collection | N14: GUI-NetworkViewer-00-3.24.robot | O14: Rendering of the applied leaf selection on map view for custom topology tree view | P14: GUI | Q14: No
A15: Y | B15: NetworkViewer-MAsterGAT-3.1 | N15: GUI-NetworkViewer-00-3.1.robot | O15: Initial display of network resources | P15: GUI | Q15: No | S15: Supported by all type of nodes as per GAT document
A16: Y | B16: NetworkViewer-MAsterGAT-3.2 | N16: GUI-NetworkViewer-00-3.2.robot | O16: Rendering of the applied selection on geographical view | P16: GUI | Q16: No
A17: Y | B17: NetworkViewer-MAsterGAT-3.3 | N17: GUI-NetworkViewer-00-3.3.robot | O17: Rendering of the applied selection on logical view | P17: GUI | Q17: No
A18: Y | B18: NetworkViewer-MAsterGAT-3.4 | N18: GUI-NetworkViewer-00-3.4.robot | O18: Zooming on the geographical and logical view | P18: GUI | Q18: No
A19: Y | B19: NetworkViewer-MAsterGAT-3.13 | N19: GUI-NetworkViewer-00-3.13.robot | O19: Viewing the relationships between nodes on geographical and logical view | P19: GUI | Q19: No
A20: Y | B20: NetworkViewer-MAsterGAT-3.14 | N20: GUI-NetworkViewer-00-3.14.robot | O20: Invocation of the Alarm Monitor for related nodes on geographical and logical view | P20: GUI | Q20: No
A21: Y | B21: NetworkViewer-MAsterGAT-3.15 | N21: GUI-NetworkViewer-00-3.15.robot | O21: Initial display of network resources for custom topology | P21: GUI | Q21: No
A22: Y | B22: NetworkViewer-MAsterGAT-3.16 | N22: GUI-NetworkViewer-00-3.16.robot | O22: Rendering of the applied node selection on map view for custom topology tree view. | P22: GUI | Q22: No

Sheet NHC
A1: Execution_Flag | B1: Test Case | C1: Node | D1: ProfileName | E1: Description | F1: Labels | G1: ReportDesc | H1: NodeType | I1: ReportName | J1: Health Check Category | K1: Hostname | L1: UserName | M1: Password | N1: Bladeinformation | O1: BladeName | P1: BladeUserName | Q1: BladePassword | R1: BladeRootPassword | S1: Robot_File_Name | T1: Description | U1: Mode | V1: Service affecting | W1: Comment | X1: Node Support Information
A2: Y | B2: NHC-4.1 | C2: BB46 | I2: CTAF-NHC-REPORT | J2: PRE_UPGRADE | S2: GUI-NHC-01-4.1.robot | T2: Create Node Health Check Reports with Nhc_Administrator role | U2: GUI | V2: No
A3: Y | B3: NHC-4.5 | I3: CTAF-NHC-REPORT | S3: GUI-NHC-02-4.5.robot | T3: Delete Node Health Check reports with Nhc_Administrator | U3: GUI | V3: No
A4: Y | B4: NHC-4.2 | D4: Health_check_profile_gat | I4: Report_Gat_testing | S4: GUI-NHC-02-4.2.robot | T4: View Health Check Reports with Nhc_Administrator/Nhc_Operator role | U4: GUI | V4: No
A5: Y | B5: NHC-4.9 | D5: Health_check_profile_gat | E5: Gat Testing | F5: POSTUPGRADE | H5: ERBS | S5: GUI-NHC-00-4.9.robot | T5: View Health Check Profile with Nhc_Administrator and Nhc_Operator role | U5: GUI | V5: No
A6: Y | B6: NHC-4.11 | C6: CBT01-02-BB6648 | D6: Health_check_profile_gat | G6: Gat Testing | I6: Report_Gat_testing | S6: GUI-NHC-01-4.11.robot | T6: Create Health Check Profile with Nhc_Administrator role | U6: GUI | V6: No
A7: Y | B7: Context Based Help | S7: GUI-NHC-00-3.9.robot | T7: Context Based Help | U7: GUI | V7: No
A8: Y | B8: Deleting Acceptance Criteria | S8: GUI-NHC-00-3.10.robot | T8: Deleting Acceptance Criteria | U8: GUI | V8: No
A9: Y | B9: NHC Reports Housekeeping | K9: 131.160.99.68 | L9: root | M9: 123shroot | N9: svc-1-shmcoreserv | O9: SCP-1 | P9: litp-admin | Q9: 123shroot | R9: 123shroot | S9: CLI-NHC-00-4.3.robot | T9: NHC Reports Housekeeping | U9: CLI | V9: No
A10: Y | B10: ENM01 | C10: BB46 | S10: ENM01.robot | T10: Run NHC with Default Acceptance Criteria | U10: CLI | V10: No | W10: Python based | X10: Macro ERBS , Micro ERBS , RBS
A11: Y | B11: ENM02 | C11: BB46 | S11: ENM02.robot | T11: Run NHC with Custom Acceptance Criteria | U11: CLI | V11: No | W11: Python based
A12: Y | B12: ENM03 | C12: BB46 | S12: ENM03.robot | T12: Deleting Acceptance Criteria | U12: CLI | V12: No | W12: Python based | X12: Macro ERBS , Micro ERBS , RBS , MGW
A13: Y | B13: ENM04 | C13: BB46 | S13: ENM04.robot | T13: Run NHC Comparison | U13: CLI | V13: No | W13: Python based | X13: Node independent

Sheet Topology Browser
A1: Execution_Flag | B1: Test Case | C1: Node | D1: SubNetwork | E1: Operator_Role_Username | F1: Operator_Role_Password | G1: Robot_File_Name | H1: Description | I1: Mode | J1: Service affecting | K1: Node Support Information
A2: Y | B2: Run Node HealthCheck | C2: BB46 | G2: GUI-TopologyBrowser-00-Custom-3.7.robot | H2: Action Bar Launch Tests: - Run Node HealthCheck (*Except BSC) | I2: GUI | J2: No | K2: Mostly Supported by all type of nodes , in case of any node type incompatibility please check GAT document for respective TC.
A3: Y | B3: View Cells | C3: BB46 | G3: GUI-TopologyBrowser-00-Custom-3.8.robot | H3: Action Bar Launch Tests: - View Cells (*Except BSC) | I3: GUI | J3: No
A4: Y | B4: Launch Element Manager | C4: BB46 | G4: GUI-TopologyBrowser-00-Custom-3.9.robot | H4: Action Bar Launch Tests: - Launch Element Manager | I4: GUI | J4: No
A5: Y | B5: Launch AMOS | C5: BB46 | G5: GUI-TopologyBrowser-00-Custom-3.10.robot | H5: Action Bar Launch Tests: - Launch AMOS | I5: GUI | J5: No
A6: Y | B6: Launch Node CLI | C6: BB46 | G6: GUI-TopologyBrowser-00-Custom-3.11.robot | H6: Action Bar Launch Tests: - Launch Node CLI | I6: GUI | J6: No
A7: Y | B7: Monitor alarms and node ,view inventories,software,hardware,License and Backup | C7: BB46 | G7: GUI-TopologyBrowser-00-Custom-3.12.robot | H7: Action Bar Launch Tests: - Monitor Alarms - Monitor This Node - View SW Inventory - View Licence Inventory - View Hardware Inventory - View Backup Inventory | I7: GUI | J7: No
A8: Y | B8: FDN Search using Topology | C8: BB46 | G8: GUI-TopologyBrowser-00-3.6.robot | H8: User can copy and paste FDN path across applications | I8: GUI | J8: No
A9: Y | B9: Show how a user can search for a different object from Topology Browser | C9: BB46 | D9: SubNetwork=NETSIM | G9: GUI-TopologyBrowser-00-3.3.robot | H9: Access to Network Explorer Search from Topology Browser | I9: GUI | J9: No
A10: Y | B10: Operator User can’t edit Attributes | E10: CTAF_TP_Operator | F10: Ctaf@TP1235 | G10: GUI-TopologyBrowser-00-3.4.robot | H10: Operator User can’t edit Attributes | I10: GUI | J10: No
A11: Y | B11: View Tree | G11: GUI-TopologyBrowser-00-3.1.robot | H11: View Tree | I11: GUI | J11: No
A12: Y | B12: View Network Elements Attributes | G12: GUI-TopologyBrowser-00-3.2.robot | H12: View Network Elements Attributes | I12: GUI | J12: No
A13: Y | B13: Administrator User can edit Attributes | G13: GUI-TopologyBrowser-00-3.5.robot | H13: Administrator User can edit Attributes | I13: GUI | J13: No
I23: =COUNTIF(I2:I13,"GUI") -> 12 | J23: =COUNTIF(J10:J22,"Yes") -> 0
I24: =COUNTIF(I2:I5,"CLI") -> 0

Sheet AutoID
A1: Execution_Flag | B1: Test Case | C1: Node | D1: Name | E1: Robot_File_Name | F1: Description | G1: Mode | H1: Service affecting | I1: Comment | J1: Node Support Information
A2: Y | B2: Create a Manual Profile | C2: BB46 | E2: GUI-AIA-00-3.2.robot | F2: Create a Manual Profile | G2: GUI | H2: No | J2: Mostly Supported by all type of nodes , in case of any node type incompatibility please check GAT document for respective TC.
A3: Y | B3: Create a Topology Group Range | C3: BB46 | D3: CTAF_Testing | E3: GUI-AIA-00-3.19.robot | F3: Create a Topology Group Range | G3: GUI | H3: No
A4: Y | B4: Launch Automatic ID Management from ENM launcher | E4: GUI-AIA-00-3.1.robot | F4: Launch Automatic ID Management from ENM launcher | G4: GUI | H4: No
A5: Y | B5: Perform a Manual Check Operation | E5: GUI-AIA-00-3.3.robot | F5: Perform a Manual Check Operation | G5: GUI | H5: No | I5: Dependent on GUI-AIA-00-3.2.robot

Sheet Parameter Management
A1: Execution_Flag | B1: Test Case | C1: NodeType | D1: Node | E1: Original Parameter Value | F1: Modified Parameter Value | G1: Robot_File_Name | H1: Description | I1: Mode | J1: Service affecting | K1: Node Support Information
A2: Y | B2: GUI-CPM-3.1 | C2: RadioNode | D2: BB46 | E2: RadioNode | F2: Test | G2: GUI-CPM-00-3.1.robot | H2: View and modify the parameters | I2: GUI | J2: No | K2: Mostly Supported by all type of nodes , in case of any node type incompatibility please check GAT document for respective TC.
A3: Y | B3: GUI-CPM-3.2 | C3: RadioNode | E3: RadioNode | F3: Test | G3: GUI-CPM-00-3.2.robot | H3: Modify multiple parameters on an MO class in Parameter Management GUI and save changes to | I3: GUI | J3: No
A4: Y | B4: GUI-CPM-3.3 | C4: RadioNode | G4: GUI-CPM-00-3.3.robot | H4: View parameters on an MO class in Parameter Management GUI using a Collection | I4: GUI | J4: No
A5: Y | B5: GUI-CPM-3.4 | C5: RadioNode | D5: BB46 | G5: GUI-CPM-00-3.4.robot | H5: View parameters on an MO class in Parameter Management GUI using an Unsaved Search | I5: GUI | J5: No

Sheet FMX
A1: Execution_Flag | B1: Test Case | C1: module_name | D1: Parameter_value | E1: Host | F1: UserName | G1: Password | H1: FMX VM Name | I1: ImportFileName | J1: Robot_File_Name | K1: Description | L1: Mode | M1: Service affecting | N1: Comment | O1: Node Support Information
A2: Y | B2: List Loaded modules-FMX CLI | E2: 131.160.99.68 | F2: root | G2: 123shroot | H2: svc-2-fmx | J2: CLI-FMX-00-3.2.6.robot | K2: List Loaded modules-FMX CLI | L2: CLI | M2: No | O2: Mostly Supported by all type of nodes , in case of any node type incompatibility please check GAT document for respective TC.
A3: Y | B3: FMX-3.1.18 | C3: RNX_HealthCheck | J3: GUI-FMX-00-3.1.18.robot | K3: View module parameters | L3: GUI | M3: No
A4: Y | B4: FMX-3.1.19 | C4: RNX_HealthCheck | D4: 18 | J4: GUI-FMX-00-3.1.19.robot | K4: Edit module parameters | L4: GUI | M4: No
A5: Y | B5: FMX-3.1.20 | C5: RNX_HealthCheck | J5: GUI-FMX-00-3.1.20.robot | K5: View module statistics | L5: GUI | M5: No
A6: Y | B6: FMX-3.1.21 | C6: RNX_HealthCheck | J6: GUI-FMX-00-3.1.21.robot | K6: Export module statistics to CSV file | L6: GUI | M6: No
A7: Y | B7: FMX-3.1.22 | C7: RNX_HealthCheck | J7: GUI-FMX-00-3.1.22.robot | K7: Deactivate rule module | L7: GUI | M7: No | N7: Dependent on 3.1.13
A8: Y | B8: FMX-3.1.23 | C8: RNX_HealthCheck | J8: GUI-FMX-00-3.1.23.robot | K8: Unload rule module | L8: GUI | M8: No | N8: Dependent on 3.1.22
A9: Y | B9: Upload module into Export | I9: SimpleModule2-1.1.fmx,wait5n10-1.0.fmx | J9: GUI-FMX-01-3.1.9.robot | K9: Upload module into Export | L9: GUI | M9: No
A10: Y | B10: Import module into Archive | C10: SimpleModule2 | J10: GUI-FMX-02-3.1.10.robot | K10: Import module into Archive | L10: GUI | M10: No | N10: Dependent On 3.1.9
A11: Y | B11: Load modules into Engine | C11: SimpleModule2 | J11: GUI-FMX-03-3.1.11.robot | K11: Load modules into Engine | L11: GUI | M11: No | N11: Dependent On 3.1.10
A12: Y | B12: Start the rule trace | J12: GUI-FMX-00-3.1.12.robot | K12: Start the rule trace | L12: GUI | M12: No
A13: Y | B13: Activate rule module | C13: RNX_HealthCheck | J13: GUI-FMX-00-3.1.13.robot | K13: Activate rule module | L13: GUI | M13: No
A14: Y | B14: Verify rule trace | C14: RNX_HealthCheck | J14: GUI-FMX-00-3.1.14.robot | K14: Verify rule trace | L14: GUI | M14: No | N14: Dependent On 3.1.12
A15: Y | B15: List Loaded modules-FMX | J15: GUI-FMX-00-3.1.6.robot | K15: List Loaded modules-FMX | L15: GUI | M15: No
A16: Y | B16: List Modules Export | J16: GUI-FMX-00-3.1.7.robot | K16: List Modules Export | L16: GUI | M16: No
A17: Y | B17: List Modules Archive | J17: GUI-FMX-00-3.1.8.robot | K17: List Modules Archive | L17: GUI | M17: No
A18: Y | B18: Stop the rule trace | J18: GUI-FMX-00-3.1.15.robot | K18: Stop the rule trace | L18: GUI | M18: No
A19: Y | B19: Export rule trace to CSV file | J19: GUI-FMX-00-3.1.16.robot | K19: Export rule trace to CSV file | L19: GUI | M19: No
A20: Y | B20: Clear the rule trace | J20: GUI-FMX-00-3.1.17.robot | K20: Clear the rule trace | L20: GUI | M20: No
M21: =COUNTIF(M2:M20,"Yes") -> 0

Sheet Cell Management
A1: Execution_Flag | B1: Test Case | C1: Node | D1: Robot_File_Name | E1: Description | F1: Mode | G1: Service affecting | H1: Comments | I1: Node Support Information
A2: Y | B2: Read EUtranCell/UtranCell/GeranCell/NR Cell data for an LTE/WCDMA/GSM/NR node | C2: BB46 | D2: GUI-CellManagement-00-3.2.1.robot | E2: Read EUtranCell/UtranCell/GeranCell/NR Cell data for an LTE/WCDMA/GSM/gNodeB Baseband node | F2: GUI | G2: No | I2: Mostly Supported by all type of nodes , in case of any node type incompatibility please check GAT document for respective TC.
A3: Y | B3: Lock cell | C3: CBT01-02-BB6648 | D3: GUI-CellManagament-01-Custom-3.1.robot | E3: Lock cell | F3: GUI | G3: Yes
A4: Y | B4: Unlock cell | C4: CBT01-02-BB6648 | D4: GUI-CellManagament-02-Custom-3.2.robot | E4: Unlock cell | F4: GUI | G4: Yes
A5: Y | B5: View Relation | C5: CBT01-02-BB6648 | D5: GUI-CellManagement-00-Custom-3.3.robot | E5: View Relations | F5: GUI | G5: No
A6: Y | B6: Launch Cell Management GUI | D6: GUI-CellManagement-00-3.1.7.robot | E6: Launch Cell Management GUI | F6: GUI | G6: No

Sheet LV
A1: Execution_Flag | B1: Test Case | C1: Node | D1: Robot_File_Name | E1: Description | F1: Mode | G1: Service affecting | H1: Comment | I1: Node Support Information
A2: Y | B2: GUI-LogViewer-04 | C2: BB46 | D2: GUI-LogViewer-00-Custom-04.robot | E2: Correlate logs from ENM | F2: GUI | G2: No | I2: Mostly Supported by all type of nodes , in case of any node type incompatibility please check GAT document for respective TC.
A3: Y | B3: View Latest Logs | D3: GUI-LogViewer-00-3.1.robot | E3: View Latest Logs | F3: GUI | G3: No
A4: Y | B4: View Log details in Details Panel | D4: GUI-LogViewer-00-3.2.robot | E4: View Log details in Details Panel | F4: GUI | G4: No
A5: Y | B5: View Logs filtered by timestamp | D5: GUI-LogViewer-00-3.3.robot | E5: View Logs filtered by timestamp | F5: GUI | G5: No
A6: Y | B6: View Logs filtered by Severity | D6: GUI-LogViewer-00-3.4.robot | E6: View Logs filtered by Severity | F6: GUI | G6: No
A7: Y | B7: Configure Columns displayed on Log Viewer | D7: GUI-LogViewer-00-3.5.robot | E7: Configure Columns displayed on Log Viewer | F7: GUI | G7: No
A8: Y | B8: Launch of online ‘Help’ from Log Viewer | D8: GUI-LogViewer-00-3.6.robot | E8: Launch of online ‘Help’ from Log Viewer | F8: GUI | G8: No
A9: Y | B9: Switch To Search Box | D9: GUI-LogViewer-00-3.7.robot | E9: Switch To Search Box | F9: GUI | G9: No
A10: Y | B10: Export | D10: GUI-LogViewer-00-3.8.robot | E10: Export | F10: GUI | G10: No

Sheet IDAM
A1: Execution_Flag | B1: Test Case | C1: ImportFileName | D1: Password | E1: NewPassword | F1: FinalPassword | G1: UserName | H1: Password | I1: Email | J1: DescriptionName | K1: Robot_File_Name | L1: Description | M1: Mode | N1: Service affecting | O1: Comments | P1: Node Support Information
A2: Y | B2: user can change own password | D2: Er1c550n@1234568 | E2: Er1c550n@1234568 | F2: Er1c550n@1234568 | G2: GAT_user1234 | K2: GUI-IDAM-02-3.11.robot | L2: User Management - User can change his/her password | M2: GUI | N2: No | O2: Dependent on 3.04 | P2: Node independent
A3: Y | B3: change a user's password | D3: Er1c550n@1234568 | E3: Er1c550n@1234568 | F3: Er1c550n@1234568 | G3: GAT_user1234 | K3: GUI-IDAM-03-3.7.robot | L3: User Management - Change a User’s password | M3: GUI | N3: No | O3: Dependent on 3.11
A4: Y | B4: Update Existing User information | G4: GAT_user1234 | I4: efg.ijk@ericsson.com | K4: GUI-IDAM-04-3.5.robot | L4: User Management - Update Existing User information | M4: GUI | N4: No | O4: Dependent on 3.04
A5: Y | B5: Check User Management page | D5: Er1c550n@1234568 | G5: GAT_user1234 | K5: GUI-IDAM-03-3.9.robot | L5: User Management - Created User without SECURITY_ADMIN role cannot access User Management page. | M5: GUI | N5: No
A6: Y | B6: View user profile | D6: Er1c550n@1234568 | G6: GAT_user1234 | K6: GUI-IDAM-06-3.10.robot | L6: User Management - User can view his/her profile | M6: GUI | N6: No | O6: Dependent on 3.04
A7: Y | B7: Modify a traget group | J7: BB46 | K7: GUI-IDAM-15-3.27.robot | L7: Target Group Management UI - Assign/Unassign target to/from a target group | M7: GUI | N7: No
A8: Y | B8: Assign targets using saved searches | J8: BB46 | K8: GUI-IDAM-17-3.29.robot | L8: Target Group Management UI - Assign target to target group (using saved searches) | M8: GUI | N8: No
A9: Y | B9: Create Role | J9: AContractor_role1 | K9: GUI-IDAM-11-3.12.robot | L9: Role Management - Create a Role | M9: GUI | N9: No
A10: Y | B10: Update existing Role information | J10: AContractor_role1 | K10: GUI-IDAM-12-3.18.robot | L10: Role Management - Update existing Role information | M10: GUI | N10: No | O10: Dependent on 3.12
